<?xml version="1.0" encoding="utf-8"?>
<!-- This URDF was automatically created by SolidWorks to URDF Exporter! Originally created by Stephen Brawner (brawner@gmail.com) 
     Commit Version: 1.5.1-0-g916b5db  Build Version: 1.5.7152.31018
     For more information, please see http://wiki.ros.org/sw_urdf_exporter -->
<robot
  name="0517">
  <link
    name="Body">
    <inertial>
      <origin
        xyz="0.10889 0.058557 -0.14231"
        rpy="0 0 0" />
      <mass
        value="5.3249" />
      <inertia
        ixx="0.021938"
        ixy="-4.0175E-06"
        ixz="-1.4798E-06"
        iyy="0.023203"
        iyz="-7.8034E-06"
        izz="0.014905" />
    </inertial>
    <visual>
      <origin
        xyz="0 0 0"
        rpy="0 0 0" />
      <geometry>
        <mesh
          filename="package://0517/meshes/Body.STL" />
      </geometry>
      <material
        name="">
        <color
          rgba="0.75294 0.75294 0.75294 1" />
      </material>
    </visual>
    <collision>
      <origin
        xyz="0 0 0"
        rpy="0 0 0" />
      <geometry>
        <mesh
          filename="package://0517/meshes/Body.STL" />
      </geometry>
    </collision>
  </link>
  <link
    name="LFS">
    <inertial>
      <origin
        xyz="0.066688 -0.025617 0.027258"
        rpy="0 0 0" />
      <mass
        value="0.26437" />
      <inertia
        ixx="3.2075E-05"
        ixy="-1.4412E-07"
        ixz="-6.3085E-08"
        iyy="6.227E-05"
        iyz="-2.0189E-07"
        izz="6.2852E-05" />
    </inertial>
    <visual>
      <origin
        xyz="0 0 0"
        rpy="0 0 0" />
      <geometry>
        <mesh
          filename="package://0517/meshes/LFS.STL" />
      </geometry>
      <material
        name="">
        <color
          rgba="0.75294 0.75294 0.75294 1" />
      </material>
    </visual>
    <collision>
      <origin
        xyz="0 0 0"
        rpy="0 0 0" />
      <geometry>
        <mesh
          filename="package://0517/meshes/LFS.STL" />
      </geometry>
    </collision>
  </link>
  <joint
    name="LFS"
    type="prismatic">
    <origin
      xyz="0.31516 0.050812 0.026427"
      rpy="2.834 0 3.1416" />
    <parent
      link="Body" />
    <child
      link="LFS" />
    <axis
      xyz="0 0.3028 -0.95305" />
    <limit
      lower="0"
      upper="0"
      effort="0"
      velocity="0" />
  </joint>
  <link
    name="LFW">
    <inertial>
      <origin
        xyz="-0.008411 -6.9389E-18 0"
        rpy="0 0 0" />
      <mass
        value="0.21405" />
      <inertia
        ixx="0.00024438"
        ixy="-8.7843E-22"
        ixz="1.5703E-21"
        iyy="0.00013645"
        iyz="-1.3553E-20"
        izz="0.00013645" />
    </inertial>
    <visual>
      <origin
        xyz="0 0 0"
        rpy="0 0 0" />
      <geometry>
        <mesh
          filename="package://0517/meshes/LFW.STL" />
      </geometry>
      <material
        name="">
        <color
          rgba="1 1 1 1" />
      </material>
    </visual>
    <collision>
      <origin
        xyz="0 0 0"
        rpy="0 0 0" />
      <geometry>
        <mesh
          filename="package://0517/meshes/LFW.STL" />
      </geometry>
    </collision>
  </link>
  <joint
    name="LFW"
    type="continuous">
    <origin
      xyz="0 -0.047479 0.052309"
      rpy="-2.4847 0 3.1416" />
    <parent
      link="LFS" />
    <child
      link="LFW" />
    <axis
      xyz="1 0 0" />
    <limit
      effort="3.1"
      velocity="7" />
  </joint>
  <link
    name="RFS">
    <inertial>
      <origin
        xyz="0.072447 -0.031683 0.02534"
        rpy="0 0 0" />
      <mass
        value="0.26437" />
      <inertia
        ixx="3.2075E-05"
        ixy="1.4412E-07"
        ixz="6.3085E-08"
        iyy="6.227E-05"
        iyz="-2.0189E-07"
        izz="6.2852E-05" />
    </inertial>
    <visual>
      <origin
        xyz="0 0 0"
        rpy="0 0 0" />
      <geometry>
        <mesh
          filename="package://0517/meshes/RFS.STL" />
      </geometry>
      <material
        name="">
        <color
          rgba="0.75294 0.75294 0.75294 1" />
      </material>
    </visual>
    <collision>
      <origin
        xyz="0 0 0"
        rpy="0 0 0" />
      <geometry>
        <mesh
          filename="package://0517/meshes/RFS.STL" />
      </geometry>
    </collision>
  </link>
  <joint
    name="RFS"
    type="prismatic">
    <origin
      xyz="-0.10492 0.012128 0.026427"
      rpy="2.834 0 0" />
    <parent
      link="Body" />
    <child
      link="RFS" />
    <axis
      xyz="0 0.3028 -0.95305" />
    <limit
      lower="0"
      upper="0"
      effort="0"
      velocity="0" />
  </joint>
  <link
    name="RFW">
    <inertial>
      <origin
        xyz="-0.014171 0 0"
        rpy="0 0 0" />
      <mass
        value="0.21405" />
      <inertia
        ixx="0.00024438"
        ixy="7.438E-22"
        ixz="-2.9693E-21"
        iyy="0.00013645"
        iyz="0"
        izz="0.00013645" />
    </inertial>
    <visual>
      <origin
        xyz="0 0 0"
        rpy="0 0 0" />
      <geometry>
        <mesh
          filename="package://0517/meshes/RFW.STL" />
      </geometry>
      <material
        name="">
        <color
          rgba="1 1 1 1" />
      </material>
    </visual>
    <collision>
      <origin
        xyz="0 0 0"
        rpy="0 0 0" />
      <geometry>
        <mesh
          filename="package://0517/meshes/RFW.STL" />
      </geometry>
    </collision>
  </link>
  <joint
    name="RFW"
    type="continuous">
    <origin
      xyz="0 -0.028286 0.058405"
      rpy="-0.36547 0 3.1416" />
    <parent
      link="RFS" />
    <child
      link="RFW" />
    <axis
      xyz="-1 0 0" />
    <limit
      effort="3.1"
      velocity="7" />
  </joint>
  <link
    name="LBS">
    <inertial>
      <origin
        xyz="0.075402 -0.020601 0.012626"
        rpy="0 0 0" />
      <mass
        value="0.19701" />
      <inertia
        ixx="1.688E-05"
        ixy="-4.8069E-21"
        ixz="2.2036E-20"
        iyy="5.0218E-05"
        iyz="1.0509E-06"
        izz="4.7245E-05" />
    </inertial>
    <visual>
      <origin
        xyz="0 0 0"
        rpy="0 0 0" />
      <geometry>
        <mesh
          filename="package://0517/meshes/LBS.STL" />
      </geometry>
      <material
        name="">
        <color
          rgba="0.75294 0.75294 0.75294 1" />
      </material>
    </visual>
    <collision>
      <origin
        xyz="0 0 0"
        rpy="0 0 0" />
      <geometry>
        <mesh
          filename="package://0517/meshes/LBS.STL" />
      </geometry>
    </collision>
  </link>
  <joint
    name="LBS"
    type="prismatic">
    <origin
      xyz="0.31516 0.23081 0.01777"
      rpy="2.834 0 3.1416" />
    <parent
      link="Body" />
    <child
      link="LBS" />
    <axis
      xyz="0 0.3028 -0.95305" />
    <limit
      lower="0"
      upper="0"
      effort="0"
      velocity="0" />
  </joint>
  <link
    name="LBC">
    <inertial>
      <origin
        xyz="3.6952E-07 -0.041409 0"
        rpy="0 0 0" />
      <mass
        value="0.022754" />
      <inertia
        ixx="9.8996E-06"
        ixy="2.3871E-10"
        ixz="-4.3943E-22"
        iyy="3.7156E-06"
        iyz="3.686E-22"
        izz="1.0825E-05" />
    </inertial>
    <visual>
      <origin
        xyz="0 0 0"
        rpy="0 0 0" />
      <geometry>
        <mesh
          filename="package://0517/meshes/LBC.STL" />
      </geometry>
      <material
        name="">
        <color
          rgba="0.79216 0.81961 0.93333 1" />
      </material>
    </visual>
    <collision>
      <origin
        xyz="0 0 0"
        rpy="0 0 0" />
      <geometry>
        <mesh
          filename="package://0517/meshes/LBC.STL" />
      </geometry>
    </collision>
  </link>
  <joint
    name="LBC"
    type="continuous">
    <origin
      xyz="0.041161 -0.016816 0.00071326"
      rpy="-1.8784 0 3.1416" />
    <parent
      link="LBS" />
    <child
      link="LBC" />
    <axis
      xyz="0 1 0" />
  </joint>
  <link
    name="LBW">
    <inertial>
      <origin
        xyz="-1.2669E-05 0 0"
        rpy="0 0 0" />
      <mass
        value="0.052036" />
      <inertia
        ixx="2.1966E-05"
        ixy="-1.0033E-21"
        ixz="1.1349E-21"
        iyy="1.254E-05"
        iyz="0"
        izz="1.254E-05" />
    </inertial>
    <visual>
      <origin
        xyz="0 0 0"
        rpy="0 0 0" />
      <geometry>
        <mesh
          filename="package://0517/meshes/LBW.STL" />
      </geometry>
      <material
        name="">
        <color
          rgba="1 1 1 1" />
      </material>
    </visual>
    <collision>
      <origin
        xyz="0 0 0"
        rpy="0 0 0" />
      <geometry>
        <mesh
          filename="package://0517/meshes/LBW.STL" />
      </geometry>
    </collision>
  </link>
  <joint
    name="LBW"
    type="continuous">
    <origin
      xyz="0 -0.0698 0"
      rpy="-2.9677 0 0" />
    <parent
      link="LBC" />
    <child
      link="LBW" />
    <axis
      xyz="1 0 0" />
    <limit
      effort="3.1"
      velocity="7" />
  </joint>
  <link
    name="RBS">
    <inertial>
      <origin
        xyz="0.075402 -0.020601 0.012626"
        rpy="0 0 0" />
      <mass
        value="0.19701" />
      <inertia
        ixx="1.688E-05"
        ixy="1.0291E-20"
        ixz="-2.4349E-20"
        iyy="5.0218E-05"
        iyz="1.0509E-06"
        izz="4.7245E-05" />
    </inertial>
    <visual>
      <origin
        xyz="0 0 0"
        rpy="0 0 0" />
      <geometry>
        <mesh
          filename="package://0517/meshes/RBS.STL" />
      </geometry>
      <material
        name="">
        <color
          rgba="0.75294 0.75294 0.75294 1" />
      </material>
    </visual>
    <collision>
      <origin
        xyz="0 0 0"
        rpy="0 0 0" />
      <geometry>
        <mesh
          filename="package://0517/meshes/RBS.STL" />
      </geometry>
    </collision>
  </link>
  <joint
    name="RBS"
    type="prismatic">
    <origin
      xyz="-0.099161 0.19919 0.01777"
      rpy="2.834 0 0" />
    <parent
      link="Body" />
    <child
      link="RBS" />
    <axis
      xyz="0 0.3028 -0.95305" />
    <limit
      lower="0"
      upper="0"
      effort="0"
      velocity="0" />
  </joint>
  <link
    name="RBC">
    <inertial>
      <origin
        xyz="3.6952E-07 -0.041409 -2.7756E-17"
        rpy="0 0 0" />
      <mass
        value="0.022754" />
      <inertia
        ixx="9.8996E-06"
        ixy="2.3871E-10"
        ixz="5.294E-22"
        iyy="3.7156E-06"
        iyz="-1.0282E-21"
        izz="1.0825E-05" />
    </inertial>
    <visual>
      <origin
        xyz="0 0 0"
        rpy="0 0 0" />
      <geometry>
        <mesh
          filename="package://0517/meshes/RBC.STL" />
      </geometry>
      <material
        name="">
        <color
          rgba="0.79216 0.81961 0.93333 1" />
      </material>
    </visual>
    <collision>
      <origin
        xyz="0 0 0"
        rpy="0 0 0" />
      <geometry>
        <mesh
          filename="package://0517/meshes/RBC.STL" />
      </geometry>
    </collision>
  </link>
  <joint
    name="RBC"
    type="continuous">
    <origin
      xyz="0.041161 -0.016816 0.00071326"
      rpy="-1.2632 0.0048755 -0.015346" />
    <parent
      link="RBS" />
    <child
      link="RBC" />
    <axis
      xyz="0 1 0" />
  </joint>
  <link
    name="RBW">
    <inertial>
      <origin
        xyz="-1.2669E-05 0 0"
        rpy="0 0 0" />
      <mass
        value="0.052036" />
      <inertia
        ixx="2.1966E-05"
        ixy="2.1176E-22"
        ixz="1.1779E-21"
        iyy="1.254E-05"
        iyz="-1.2705E-21"
        izz="1.254E-05" />
    </inertial>
    <visual>
      <origin
        xyz="0 0 0"
        rpy="0 0 0" />
      <geometry>
        <mesh
          filename="package://0517/meshes/RBW.STL" />
      </geometry>
      <material
        name="">
        <color
          rgba="1 1 1 1" />
      </material>
    </visual>
    <collision>
      <origin
        xyz="0 0 0"
        rpy="0 0 0" />
      <geometry>
        <mesh
          filename="package://0517/meshes/RBW.STL" />
      </geometry>
    </collision>
  </link>
  <joint
    name="RBW"
    type="continuous">
    <origin
      xyz="0 -0.0698 0"
      rpy="-0.70587 0 -3.1416" />
    <parent
      link="RBC" />
    <child
      link="RBW" />
    <axis
      xyz="-1 0 0" />
    <limit
      effort="3.1"
      velocity="7" />
  </joint>
  <link
    name="front_cam">
    <inertial>
      <origin
        xyz="0.049836 0.061784 0.068723"
        rpy="0 0 0" />
      <mass
        value="0.043612" />
      <inertia
        ixx="4.2948E-06"
        ixy="-8.8579E-10"
        ixz="-1.0181E-09"
        iyy="2.2106E-05"
        iyz="2.1758E-08"
        izz="2.3571E-05" />
    </inertial>
    <visual>
      <origin
        xyz="0 0 0"
        rpy="0 0 0" />
      <geometry>
        <mesh
          filename="package://0517/meshes/front_cam.STL" />
      </geometry>
      <material
        name="">
        <color
          rgba="0.79216 0.81961 0.93333 1" />
      </material>
    </visual>
    <collision>
      <origin
        xyz="0 0 0"
        rpy="0 0 0" />
      <geometry>
        <mesh
          filename="package://0517/meshes/front_cam.STL" />
      </geometry>
    </collision>
  </link>
  <joint
    name="front_cam"
    type="fixed">
    <origin
      xyz="0.058161 0.080278 0.069504"
      rpy="1.5708 0 0" />
    <parent
      link="Body" />
    <child
      link="front_cam" />
    <axis
      xyz="0 0 0" />
  </joint>
  <link
    name="ball_cam">
    <inertial>
      <origin
        xyz="0.049836 0.061784 -0.0037462"
        rpy="0 0 0" />
      <mass
        value="0.043612" />
      <inertia
        ixx="4.2948E-06"
        ixy="-8.8526E-10"
        ixz="-1.0184E-09"
        iyy="2.2106E-05"
        iyz="2.1758E-08"
        izz="2.3571E-05" />
    </inertial>
    <visual>
      <origin
        xyz="0 0 0"
        rpy="0 0 0" />
      <geometry>
        <mesh
          filename="package://0517/meshes/ball_cam.STL" />
      </geometry>
      <material
        name="">
        <color
          rgba="0.79216 0.81961 0.93333 1" />
      </material>
    </visual>
    <collision>
      <origin
        xyz="0 0 0"
        rpy="0 0 0" />
      <geometry>
        <mesh
          filename="package://0517/meshes/ball_cam.STL" />
      </geometry>
    </collision>
  </link>
  <joint
    name="ball_cam"
    type="fixed">
    <origin
      xyz="0.058165 0.048961 0.044286"
      rpy="2.2021 0 0" />
    <parent
      link="Body" />
    <child
      link="ball_cam" />
    <axis
      xyz="0 0 0" />
  </joint>
  <link
    name="Lidar">
    <inertial>
      <origin
        xyz="-0.078493 -0.74443 -0.13345"
        rpy="0 0 0" />
      <mass
        value="0.073085" />
      <inertia
        ixx="1.9581E-05"
        ixy="4.2839E-07"
        ixz="-1.0393E-07"
        iyy="4.1418E-05"
        iyz="-9.4271E-09"
        izz="2.4125E-05" />
    </inertial>
    <visual>
      <origin
        xyz="0 0 0"
        rpy="0 0 0" />
      <geometry>
        <mesh
          filename="package://0517/meshes/Lidar.STL" />
      </geometry>
      <material
        name="">
        <color
          rgba="0.79216 0.81961 0.93333 1" />
      </material>
    </visual>
    <collision>
      <origin
        xyz="0 0 0"
        rpy="0 0 0" />
      <geometry>
        <mesh
          filename="package://0517/meshes/Lidar.STL" />
      </geometry>
    </collision>
  </link>
  <joint
    name="Lidar"
    type="fixed">
    <origin
      xyz="0.24092 0.098561 -0.57169"
      rpy="-1.5708 0 -1.5708" />
    <parent
      link="Body" />
    <child
      link="Lidar" />
    <axis
      xyz="0 0 0" />
  </joint>
</robot>